Workbook

Sheet FSM
A1: 3 Statement Financial Model of Microsoft
E5: Active Case | F5: ='Sensitivity Analysis'!E2 -> 2
D8: Income Statement | E8: 45107 | F8: =EOMONTH(E8,12) -> 45473 | G8: =EOMONTH(F8,12) -> 45838 | H8: =EOMONTH(G8,12) -> 46203 | I8: =EOMONTH(H8,12) -> 46568 | J8: =EOMONTH(I8,12) -> 46934 | K8: =EOMONTH(J8,12) -> 47299 | L8: =EOMONTH(K8,12) -> 47664
D10: Product | E10: 64699 | F10: 64773 | G10: 63946 | H10: =H12*H30 -> 70092.362 | I10: =I12*I30 -> 75908.469 | J10: =J12*J30 -> 82248.383 | K10: =K12*K30 -> 86425.295 | L10: =L12*L30 -> 90361.303
D11: Service and other | E11: 147216 | F11: 180349 | G11: 217778 | H11: =H12*H31 -> 256707.48 | I11: =I12*I31 -> 299911.35 | J11: =J12*J31 -> 351823.5 | K11: =K12*K31 -> 401905.58 | L11: =L12*L31 -> 459010.93
D12: Total Revenue | E12: =E10+E11 -> 211915 | F12: =F10+F11 -> 245122 | G12: =G10+G11 -> 281724 | H12: =G12*(1+H29) -> 326799.84 | I12: =H12*(1+I29) -> 375819.82 | J12: =I12*(1+J29) -> 434071.89 | K12: =J12*(1+K29) -> 488330.87 | L12: =K12*(1+L29) -> 549372.23
D13: Product COGS | E13: 17804 | F13: 15272 | G13: 13501 | H13: =H10*H32 -> 14018.472 | I13: =I10*I32 -> 15181.694 | J13: =J10*J32 -> 16449.677 | K13: =K10*K32 -> 16420.806 | L13: =L10*L32 -> 17168.648
D14: Service and other COGS | E14: 48059 | F14: 58842 | G14: 74330 | H14: =H11*H33 -> 89847.617 | I14: =I11*I33 -> 104968.97 | J14: =J11*J33 -> 126656.46 | K14: =K11*K33 -> 140666.95 | L14: =L11*L33 -> 156063.72
D15: Total COGS | E15: =SUM(E13:E14) -> 65863 | F15: =SUM(F13:F14) -> 74114 | G15: =SUM(G13:G14) -> 87831 | H15: =SUM(H13:H14) -> 103866.09 | I15: =SUM(I13:I14) -> 120150.67 | J15: =SUM(J13:J14) -> 143106.14 | K15: =SUM(K13:K14) -> 157087.76 | L15: =SUM(L13:L14) -> 173232.36
D16: Gross Margin | E16: =E12-E15 -> 146052 | F16: =F12-F15 -> 171008 | G16: =G12-G15 -> 193893 | H16: =H12-H15 -> 222933.75 | I16: =I12-I15 -> 255669.15 | J16: =J12-J15 -> 290965.75 | K16: =K12-K15 -> 331243.11 | L16: =L12-L15 -> 376139.87
D17: R&D | E17: 27195 | F17: 29510 | G17: 32488 | H17: =H12*H34 -> 40849.98 | I17: =I12*I34 -> 46977.477 | J17: =J12*J34 -> 54258.986 | K17: =K12*K34 -> 58599.705 | L17: =L12*L34 -> 65924.668
D18: Sales and marketing | E18: 22759 | F18: 24456 | G18: 25654 | H18: =H12*H35 -> 28451.441 | I18: =I12*I35 -> 31215.877 | J18: =J12*J35 -> 34318.051 | K18: =K12*K35 -> 36654.484 | L18: =L12*L35 -> 39038.805
D19: General and Administration | E19: 7575 | F19: 7609 | G19: 7223 | H19: =H12*H36 -> 7725.0803 | I19: =I12*I36 -> 8132.2027 | J19: =J12*J36 -> 8524.5504 | K19: =K12*K36 -> 8613.4574 | L19: =L12*L36 -> 8591.3952
D20: Operating Income | E20: =E16-SUM(E17:E19) -> 88523 | F20: =F16-SUM(F17:F19) -> 109433 | G20: =G16-SUM(G17:G19) -> 128528 | H20: =H16-SUM(H17:H19) -> 145907.25 | I20: =I16-SUM(I17:I19) -> 169343.59 | J20: =J16-SUM(J17:J19) -> 193864.16 | K20: =K16-SUM(K17:K19) -> 227375.47 | L20: =L16-SUM(L17:L19) -> 262585
D21: Other income(expense), net | E21: 788 | F21: -1646 | G21: -4901 | H21: =H46 -> -6194.36 | I21: =I46 -> -6154.61 | J21: =J46 -> -6048.1 | K21: =K46 -> -5907.4 | L21: =L46 -> -5728.4
D22: Income before taxes | E22: =E20+E21 -> 89311 | F22: =F20+F21 -> 107787 | G22: =G20+G21 -> 123627 | H22: =H20+H21 -> 139712.89 | I22: =I20+I21 -> 163188.98 | J22: =J20+J21 -> 187816.06 | K22: =K20+K21 -> 221468.07 | L22: =L20+L21 -> 256856.6
D23: Provision for income tax | E23: 16950 | F23: 19651 | G23: 21795 | H23: =H22*H37 -> 25539.516 | I23: =I22*I37 -> 29830.946 | J23: =J22*J37 -> 34332.776 | K23: =K22*K37 -> 40484.363 | L23: =L22*L37 -> 46953.387
D24: Net Income | E24: =E22-E23 -> 72361 | F24: =F22-F23 -> 88136 | G24: =G22-G23 -> 101832 | H24: =H22-H23 -> 114173.37 | I24: =I22-I23 -> 133358.04 | J24: =J22-J23 -> 153483.29 | K24: =K22-K23 -> 180983.71 | L24: =L22-L23 -> 209903.21
D29: Revenue Growth | F29: =(F12-E12)/E12 -> 0.15669962 | G29: =(G12-F12)/F12 -> 0.14932156 | H29: ='Sensitivity Analysis'!H9 -> 0.16 | I29: ='Sensitivity Analysis'!I9 -> 0.15 | J29: ='Sensitivity Analysis'!J9 -> 0.155 | K29: ='Sensitivity Analysis'!K9 -> 0.125 | L29: ='Sensitivity Analysis'!L9 -> 0.125 | M29: Step Function
D30: Revenue from Product | E30: =E10/E12 -> 0.30530637 | F30: =F10/F12 -> 0.26424801 | G30: =G10/G12 -> 0.22698102 | H30: =G30-$M$30 -> 0.21448102 | I30: =H30-$M$30 -> 0.20198102 | J30: =I30-$M$30 -> 0.18948102 | K30: =J30-$M$30 -> 0.17698102 | L30: =K30-$M$30 -> 0.16448102 | M30: 0.0125
D31: Revenue from Services and other | E31: =E11/E12 -> 0.69469363 | F31: =F11/F12 -> 0.73575199 | G31: =G11/G12 -> 0.77301898 | H31: =G31+$M$31 -> 0.78551898 | I31: =H31+$M$31 -> 0.79801898 | J31: =I31+$M$31 -> 0.81051898 | K31: =J31+$M$31 -> 0.82301898 | L31: =K31+$M$31 -> 0.83551898 | M31: 0.0125
D32: Product COGS/Product Revenue | E32: =E13/E10 -> 0.275182 | F32: =F13/F10 -> 0.23577725 | G32: =G13/G10 -> 0.21113127 | H32: 0.2 | I32: 0.2 | J32: 0.2 | K32: 0.19 | L32: 0.19
D33: Service and other COGS/Services and other Revenue | E33: =E14/E11 -> 0.32645229 | F33: =F14/F11 -> 0.3262674 | G33: =G14/G11 -> 0.34131088 | H33: ='Sensitivity Analysis'!H10 -> 0.35 | I33: ='Sensitivity Analysis'!I10 -> 0.35 | J33: ='Sensitivity Analysis'!J10 -> 0.36 | K33: ='Sensitivity Analysis'!K10 -> 0.35 | L33: ='Sensitivity Analysis'!L10 -> 0.34
D34: R&D as % of Total Revenue | E34: =E17/E12 -> 0.12832975 | F34: =F17/F12 -> 0.12038903 | G34: =G17/G12 -> 0.11531854 | H34: ='Sensitivity Analysis'!H11 -> 0.125 | I34: ='Sensitivity Analysis'!I11 -> 0.125 | J34: ='Sensitivity Analysis'!J11 -> 0.125 | K34: ='Sensitivity Analysis'!K11 -> 0.12 | L34: ='Sensitivity Analysis'!L11 -> 0.12
D35: Sales and Marketing as % of Total Revenue | E35: =E18/E12 -> 0.10739683 | F35: =F18/F12 -> 0.099770726 | G35: =G18/G12 -> 0.091060754 | H35: =G35-$M$35 -> 0.087060754 | I35: =H35-$M$35 -> 0.083060754 | J35: =I35-$M$35 -> 0.079060754 | K35: =J35-$M$35 -> 0.075060754 | L35: =K35-$M$35 -> 0.071060754 | M35: 0.004
D36: General and Admin as % of Total Revenue | E36: =E19/E12 -> 0.035745464 | F36: =F19/F12 -> 0.031041685 | G36: =G19/G12 -> 0.025638568 | H36: =G36-$M$36 -> 0.023638568 | I36: =H36-$M$36 -> 0.021638568 | J36: =I36-$M$36 -> 0.019638568 | K36: =J36-$M$36 -> 0.017638568 | L36: =K36-$M$36 -> 0.015638568 | M36: 0.002
D37: Tax rate | E37: =E23/E22 -> 0.18978625 | F37: =F23/F22 -> 0.18231327 | G37: =G23/G22 -> 0.17629644 | H37: ='Sensitivity Analysis'!H12 -> 0.1828 | I37: ='Sensitivity Analysis'!I12 -> 0.1828 | J37: ='Sensitivity Analysis'!J12 -> 0.1828 | K37: ='Sensitivity Analysis'!K12 -> 0.1828 | L37: ='Sensitivity Analysis'!L12 -> 0.1828
D39: Other income (expense)net | F39: 45473 | G39: =EOMONTH(F39,12) -> 45838 | H39: =EOMONTH(G39,12) -> 46203 | I39: =EOMONTH(H39,12) -> 46568 | J39: =EOMONTH(I39,12) -> 46934 | K39: =EOMONTH(J39,12) -> 47299 | L39: =EOMONTH(K39,12) -> 47664
D40: interest and dividend income | F40: 3157 | G40: 2647 | H40: 1287 | I40: 1093 | J40: 1210 | K40: 1448 | L40: 1627
D41: interest expense | F41: -2935 | G41: -2385 | H41: =-H175 -> -2318.36 | I41: =-I175 -> -2084.61 | J41: =-J175 -> -2095.1 | K41: =-K175 -> -2192.4 | L41: =-L175 -> -2192.4
D42: net recognized loss on investment | F42: -118 | G42: -349 | H42: -349 | I42: -349 | J42: -349 | K42: -349 | L42: -349
D43: net loss on derivatives | F43: -187 | G43: -260 | H43: -260 | I43: -260 | J43: -260 | K43: -260 | L43: -260
D44: net gain (loss) on foreign currency transaction | F44: -244 | G44: 171 | H44: 171 | I44: 171 | J44: 171 | K44: 171 | L44: 171
D45: other,net | F45: -1319 | G45: -4725 | H45: -4725 | I45: -4725 | J45: -4725 | K45: -4725 | L45: -4725
D46: total | F46: =SUM(F40:F45) -> -1646 | G46: =SUM(G40:G45) -> -4901 | H46: =SUM(H40:H45) -> -6194.36 | I46: =SUM(I40:I45) -> -6154.61 | J46: =SUM(J40:J45) -> -6048.1 | K46: =SUM(K40:K45) -> -5907.4 | L46: =SUM(L40:L45) -> -5728.4
D52: Balance Sheet | E52: 45107 | F52: =EOMONTH(E52,12) -> 45473 | G52: =EOMONTH(F52,12) -> 45838 | H52: =EOMONTH(G52,12) -> 46203 | I52: =EOMONTH(H52,12) -> 46568 | J52: =EOMONTH(I52,12) -> 46934 | K52: =EOMONTH(J52,12) -> 47299 | L52: =EOMONTH(K52,12) -> 47664
D54: Cash and Cash Equivalent | F54: 18315 | G54: 30242 | H54: =G54+H126 -> 39717.876 | I54: =H54+I126 -> 37282.522 | J54: =I54+J126 -> 49757.07 | K54: =J54+K126 -> 60923.562 | L54: =K54+L126 -> 70440.069
C55: N/A | D55: Short term investments | F55: 57228 | G55: 64323 | H55: 64323 | I55: 64323 | J55: 64323 | K55: 64323 | L55: 64323
D56: Accounts receivables | F56: 56924 | G56: 69905 | H56: =H91*H12/365 -> 78490.809 | I56: =I91*I12/365 -> 90264.43 | J56: =J91*J12/365 -> 104255.42 | K56: =K91*K12/365 -> 117287.34 | L56: =L91*L12/365 -> 131948.26
D57: Inventories | F57: 1246 | G57: 938 | H57: =G57*(1+H29) -> 1088.08 | I57: =H57*(1+I29) -> 1251.292 | J57: =I57*(1+J29) -> 1445.2423 | K57: =J57*(1+K29) -> 1625.8975 | L57: =K57*(1+L29) -> 1829.1347 | M57: Grown with Revenue
...

Sheet Sensitivity Analysis
E2: 2 | F2: Active Case
E4: 1 | F4: Best Case
E5: 2 | F5: Street Case
E6: 3 | F6: Weak Case
D8: Sensitivity Analysis | E8: 45107 | F8: =EOMONTH(E8,12) -> 45473 | G8: =EOMONTH(F8,12) -> 45838 | H8: =EOMONTH(G8,12) -> 46203 | I8: =EOMONTH(H8,12) -> 46568 | J8: =EOMONTH(I8,12) -> 46934 | K8: =EOMONTH(J8,12) -> 47299 | L8: =EOMONTH(K8,12) -> 47664
D9: Revenue growth | H9: =CHOOSE($E$2,H16,H17,H18) -> 0.16 | I9: =CHOOSE($E$2,I16,I17,I18) -> 0.15 | J9: =CHOOSE($E$2,J16,J17,J18) -> 0.155 | K9: =CHOOSE($E$2,K16,K17,K18) -> 0.125 | L9: =CHOOSE($E$2,L16,L17,L18) -> 0.125
D10: Service and other COGS/Services and other Revenue | H10: =CHOOSE($E$2,H21,H22,H23) -> 0.35 | I10: =CHOOSE($E$2,I21,I22,I23) -> 0.35 | J10: =CHOOSE($E$2,J21,J22,J23) -> 0.36 | K10: =CHOOSE($E$2,K21,K22,K23) -> 0.35 | L10: =CHOOSE($E$2,L21,L22,L23) -> 0.34
D11: R&D as % of Total Revenue | H11: =CHOOSE($E$2,H26,H27,H28) -> 0.125 | I11: =CHOOSE($E$2,I26,I27,I28) -> 0.125 | J11: =CHOOSE($E$2,J26,J27,J28) -> 0.125 | K11: =CHOOSE($E$2,K26,K27,K28) -> 0.12 | L11: =CHOOSE($E$2,L26,L27,L28) -> 0.12
D12: Tax rate | H12: =CHOOSE($E$2,H31,H32,H33) -> 0.1828 | I12: =CHOOSE($E$2,I31,I32,I33) -> 0.1828 | J12: =CHOOSE($E$2,J31,J32,J33) -> 0.1828 | K12: =CHOOSE($E$2,K31,K32,K33) -> 0.1828 | L12: =CHOOSE($E$2,L31,L32,L33) -> 0.1828
D15: Revenue growth | G15: OFFSET
D16: Best Case | G16: 0.01 | H16: =H17+$G$16 -> 0.17 | I16: =I17+$G$16 -> 0.16 | J16: =J17+$G$16 -> 0.165 | K16: =K17+$G$16 -> 0.135 | L16: =L17+$G$16 -> 0.135
D17: Street Case | H17: 0.16 | I17: 0.15 | J17: 0.155 | K17: 0.125 | L17: 0.125
D18: Weak Case | G18: -0.025 | H18: =H17+$G$18 -> 0.135 | I18: =I17+$G$18 -> 0.125 | J18: =J17+$G$18 -> 0.13 | K18: =K17+$G$18 -> 0.1 | L18: =L17+$G$18 -> 0.1
D20: Service and other COGS/Services and other Revenue
D21: Best Case | G21: -0.025 | H21: =H22+$G$21 -> 0.325 | I21: =I22+$G$21 -> 0.325 | J21: =J22+$G$21 -> 0.335 | K21: =K22+$G$21 -> 0.325 | L21: =L22+$G$21 -> 0.315
D22: Street Case | H22: 0.35 | I22: 0.35 | J22: 0.36 | K22: 0.35 | L22: 0.34
D23: Weak Case | G23: 0.05 | H23: =H22+$G$23 -> 0.4 | I23: =I22+$G$23 -> 0.4 | J23: =J22+$G$23 -> 0.41 | K23: =K22+$G$23 -> 0.4 | L23: =L22+$G$23 -> 0.39
D25: R&D as % of Total Revenue
D26: Best Case | G26: -0.025 | H26: =H27+$G$26 -> 0.1 | I26: =I27+$G$26 -> 0.1 | J26: =J27+$G$26 -> 0.1 | K26: =K27+$G$26 -> 0.095 | L26: =L27+$G$26 -> 0.095
D27: Street Case | H27: 0.125 | I27: 0.125 | J27: 0.125 | K27: 0.12 | L27: 0.12
D28: Weak Case | G28: 0.025 | H28: =H27+$G$28 -> 0.15 | I28: =I27+$G$28 -> 0.15 | J28: =J27+$G$28 -> 0.15 | K28: =K27+$G$28 -> 0.145 | L28: =L27+$G$28 -> 0.145
D30: Tax rate
D31: Best Case | G31: -0.01 | H31: =H32+$G$31 -> 0.1728 | I31: =I32+$G$31 -> 0.1728 | J31: =J32+$G$31 -> 0.1728 | K31: =K32+$G$31 -> 0.1728 | L31: =L32+$G$31 -> 0.1728
D32: Street Case | H32: 0.1828 | I32: 0.1828 | J32: 0.1828 | K32: 0.1828 | L32: 0.1828
D33: Weak Case | G33: 0.025 | H33: =H32+$G$33 -> 0.2078 | I33: =I32+$G$33 -> 0.2078 | J33: =J32+$G$33 -> 0.2078 | K33: =K32+$G$33 -> 0.2078 | L33: =L32+$G$33 -> 0.2078
